[2024-03-11T22:19:11.423+0000] {taskinstance.py:1979} INFO - Dependencies all met for dep_context=non-requeueable deps ti=<TaskInstance: netflix_etl_dag.extract_people_task manual__2024-03-11T21:55:01.551934+00:00 [queued]>
[2024-03-11T22:19:11.435+0000] {taskinstance.py:1979} INFO - Dependencies all met for dep_context=requeueable deps ti=<TaskInstance: netflix_etl_dag.extract_people_task manual__2024-03-11T21:55:01.551934+00:00 [queued]>
[2024-03-11T22:19:11.436+0000] {taskinstance.py:2193} INFO - Starting attempt 2 of 3
[2024-03-11T22:19:11.452+0000] {taskinstance.py:2214} INFO - Executing <Task(PythonOperator): extract_people_task> on 2024-03-11 21:55:01.551934+00:00
[2024-03-11T22:19:11.458+0000] {standard_task_runner.py:60} INFO - Started process 17754 to run task
[2024-03-11T22:19:11.462+0000] {standard_task_runner.py:87} INFO - Running: ['***', 'tasks', 'run', 'netflix_etl_dag', 'extract_people_task', 'manual__2024-03-11T21:55:01.551934+00:00', '--job-id', '85', '--raw', '--subdir', 'DAGS_FOLDER/netflix_dag.py', '--cfg-path', '/tmp/tmpa9gi394r']
[2024-03-11T22:19:11.465+0000] {standard_task_runner.py:88} INFO - Job 85: Subtask extract_people_task
[2024-03-11T22:19:11.521+0000] {task_command.py:423} INFO - Running <TaskInstance: netflix_etl_dag.extract_people_task manual__2024-03-11T21:55:01.551934+00:00 [running]> on host 472fedd09e2a
[2024-03-11T22:19:11.629+0000] {taskinstance.py:2510} INFO - Exporting env vars: AIRFLOW_CTX_DAG_EMAIL='anamsken60@gmail.com' AIRFLOW_CTX_DAG_OWNER='***' AIRFLOW_CTX_DAG_ID='netflix_etl_dag' AIRFLOW_CTX_TASK_ID='extract_people_task' AIRFLOW_CTX_EXECUTION_DATE='2024-03-11T21:55:01.551934+00:00' AIRFLOW_CTX_TRY_NUMBER='2' AIRFLOW_CTX_DAG_RUN_ID='manual__2024-03-11T21:55:01.551934+00:00'
[2024-03-11T22:19:11.639+0000] {taskinstance.py:2728} ERROR - Task failed with exception
Traceback (most recent call last):
  File "/home/airflow/.local/lib/python3.8/site-packages/urllib3/connection.py", line 174, in _new_conn
    conn = connection.create_connection(
  File "/home/airflow/.local/lib/python3.8/site-packages/urllib3/util/connection.py", line 72, in create_connection
    for res in socket.getaddrinfo(host, port, family, socket.SOCK_STREAM):
  File "/usr/local/lib/python3.8/socket.py", line 918, in getaddrinfo
    for res in _socket.getaddrinfo(host, port, family, type, proto, flags):
socket.gaierror: [Errno -2] Name or service not known

During handling of the above exception, another exception occurred:

Traceback (most recent call last):
  File "/home/airflow/.local/lib/python3.8/site-packages/urllib3/connectionpool.py", line 715, in urlopen
    httplib_response = self._make_request(
  File "/home/airflow/.local/lib/python3.8/site-packages/urllib3/connectionpool.py", line 404, in _make_request
    self._validate_conn(conn)
  File "/home/airflow/.local/lib/python3.8/site-packages/urllib3/connectionpool.py", line 1058, in _validate_conn
    conn.connect()
  File "/home/airflow/.local/lib/python3.8/site-packages/urllib3/connection.py", line 363, in connect
    self.sock = conn = self._new_conn()
  File "/home/airflow/.local/lib/python3.8/site-packages/urllib3/connection.py", line 186, in _new_conn
    raise NewConnectionError(
urllib3.exceptions.NewConnectionError: <urllib3.connection.HTTPSConnection object at 0x7fd740508a30>: Failed to establish a new connection: [Errno -2] Name or service not known

During handling of the above exception, another exception occurred:

Traceback (most recent call last):
  File "/home/airflow/.local/lib/python3.8/site-packages/requests/adapters.py", line 486, in send
    resp = conn.urlopen(
  File "/home/airflow/.local/lib/python3.8/site-packages/urllib3/connectionpool.py", line 799, in urlopen
    retries = retries.increment(
  File "/home/airflow/.local/lib/python3.8/site-packages/urllib3/util/retry.py", line 592, in increment
    raise MaxRetryError(_pool, url, error or ResponseError(cause))
urllib3.exceptions.MaxRetryError: HTTPSConnectionPool(host='api.apilayer.com', port=443): Max retries exceeded with url: /unogs/search/people?person_type=Director (Caused by NewConnectionError('<urllib3.connection.HTTPSConnection object at 0x7fd740508a30>: Failed to establish a new connection: [Errno -2] Name or service not known'))

During handling of the above exception, another exception occurred:

Traceback (most recent call last):
  File "/home/airflow/.local/lib/python3.8/site-packages/airflow/models/taskinstance.py", line 444, in _execute_task
    result = _execute_callable(context=context, **execute_callable_kwargs)
  File "/home/airflow/.local/lib/python3.8/site-packages/airflow/models/taskinstance.py", line 414, in _execute_callable
    return execute_callable(context=context, **execute_callable_kwargs)
  File "/home/airflow/.local/lib/python3.8/site-packages/airflow/operators/python.py", line 200, in execute
    return_value = self.execute_callable()
  File "/home/airflow/.local/lib/python3.8/site-packages/airflow/operators/python.py", line 217, in execute_callable
    return self.python_callable(*self.op_args, **self.op_kwargs)
  File "/opt/airflow/dags/netflix_dag.py", line 81, in extract_people
    response = requests.request("GET", url, headers=headers, data=payload)
  File "/home/airflow/.local/lib/python3.8/site-packages/requests/api.py", line 59, in request
    return session.request(method=method, url=url, **kwargs)
  File "/home/airflow/.local/lib/python3.8/site-packages/requests/sessions.py", line 589, in request
    resp = self.send(prep, **send_kwargs)
  File "/home/airflow/.local/lib/python3.8/site-packages/requests/sessions.py", line 703, in send
    r = adapter.send(request, **kwargs)
  File "/home/airflow/.local/lib/python3.8/site-packages/requests/adapters.py", line 519, in send
    raise ConnectionError(e, request=request)
requests.exceptions.ConnectionError: HTTPSConnectionPool(host='api.apilayer.com', port=443): Max retries exceeded with url: /unogs/search/people?person_type=Director (Caused by NewConnectionError('<urllib3.connection.HTTPSConnection object at 0x7fd740508a30>: Failed to establish a new connection: [Errno -2] Name or service not known'))
[2024-03-11T22:19:11.656+0000] {taskinstance.py:1149} INFO - Marking task as UP_FOR_RETRY. dag_id=netflix_etl_dag, task_id=extract_people_task, execution_date=20240311T215501, start_date=20240311T221911, end_date=20240311T221911
[2024-03-11T22:19:11.667+0000] {standard_task_runner.py:107} ERROR - Failed to execute job 85 for task extract_people_task (HTTPSConnectionPool(host='api.apilayer.com', port=443): Max retries exceeded with url: /unogs/search/people?person_type=Director (Caused by NewConnectionError('<urllib3.connection.HTTPSConnection object at 0x7fd740508a30>: Failed to establish a new connection: [Errno -2] Name or service not known')); 17754)
[2024-03-11T22:19:11.686+0000] {local_task_job_runner.py:234} INFO - Task exited with return code 1
[2024-03-11T22:19:11.706+0000] {taskinstance.py:3309} INFO - 0 downstream tasks scheduled from follow-on schedule check
