[2024-03-10T01:16:39.711+0000] {taskinstance.py:1979} INFO - Dependencies all met for dep_context=non-requeueable deps ti=<TaskInstance: netflix_etl_dag.is_api_available scheduled__2024-03-09T00:00:00+00:00 [queued]>
[2024-03-10T01:16:39.728+0000] {taskinstance.py:1979} INFO - Dependencies all met for dep_context=requeueable deps ti=<TaskInstance: netflix_etl_dag.is_api_available scheduled__2024-03-09T00:00:00+00:00 [queued]>
[2024-03-10T01:16:39.729+0000] {taskinstance.py:2193} INFO - Starting attempt 3 of 3
[2024-03-10T01:16:39.749+0000] {taskinstance.py:2214} INFO - Executing <Task(SimpleHttpOperator): is_api_available> on 2024-03-09 00:00:00+00:00
[2024-03-10T01:16:39.758+0000] {standard_task_runner.py:60} INFO - Started process 1617 to run task
[2024-03-10T01:16:39.763+0000] {standard_task_runner.py:87} INFO - Running: ['***', 'tasks', 'run', 'netflix_etl_dag', 'is_api_available', 'scheduled__2024-03-09T00:00:00+00:00', '--job-id', '11', '--raw', '--subdir', 'DAGS_FOLDER/netflix_dag.py', '--cfg-path', '/tmp/tmpnzwvhae7']
[2024-03-10T01:16:39.765+0000] {standard_task_runner.py:88} INFO - Job 11: Subtask is_api_available
[2024-03-10T01:16:39.843+0000] {task_command.py:423} INFO - Running <TaskInstance: netflix_etl_dag.is_api_available scheduled__2024-03-09T00:00:00+00:00 [running]> on host d398d0a13bdf
[2024-03-10T01:16:39.957+0000] {taskinstance.py:2510} INFO - Exporting env vars: AIRFLOW_CTX_DAG_EMAIL='anamsken60@gmail.com' AIRFLOW_CTX_DAG_OWNER='***' AIRFLOW_CTX_DAG_ID='netflix_etl_dag' AIRFLOW_CTX_TASK_ID='is_api_available' AIRFLOW_CTX_EXECUTION_DATE='2024-03-09T00:00:00+00:00' AIRFLOW_CTX_TRY_NUMBER='3' AIRFLOW_CTX_DAG_RUN_ID='scheduled__2024-03-09T00:00:00+00:00'
[2024-03-10T01:16:39.960+0000] {http.py:169} INFO - Calling HTTP method
[2024-03-10T01:16:39.973+0000] {base.py:83} INFO - Using connection ID 'netflix_api' for task execution.
[2024-03-10T01:16:39.989+0000] {base.py:83} INFO - Using connection ID 'netflix_api' for task execution.
[2024-03-10T01:16:40.002+0000] {http.py:235} WARNING - HTTPSConnectionPool(host='api.apilayer.com', port=443): Max retries exceeded with url: //unogs/search/titles/ (Caused by NewConnectionError('<urllib3.connection.HTTPSConnection object at 0x7f106221d790>: Failed to establish a new connection: [Errno -2] Name or service not known')) Tenacity will retry to execute the operation
[2024-03-10T01:16:40.005+0000] {taskinstance.py:2728} ERROR - Task failed with exception
Traceback (most recent call last):
  File "/home/airflow/.local/lib/python3.8/site-packages/urllib3/connection.py", line 174, in _new_conn
    conn = connection.create_connection(
  File "/home/airflow/.local/lib/python3.8/site-packages/urllib3/util/connection.py", line 72, in create_connection
    for res in socket.getaddrinfo(host, port, family, socket.SOCK_STREAM):
  File "/usr/local/lib/python3.8/socket.py", line 918, in getaddrinfo
    for res in _socket.getaddrinfo(host, port, family, type, proto, flags):
socket.gaierror: [Errno -2] Name or service not known

During handling of the above exception, another exception occurred:

Traceback (most recent call last):
  File "/home/airflow/.local/lib/python3.8/site-packages/urllib3/connectionpool.py", line 715, in urlopen
    httplib_response = self._make_request(
  File "/home/airflow/.local/lib/python3.8/site-packages/urllib3/connectionpool.py", line 404, in _make_request
    self._validate_conn(conn)
  File "/home/airflow/.local/lib/python3.8/site-packages/urllib3/connectionpool.py", line 1058, in _validate_conn
    conn.connect()
  File "/home/airflow/.local/lib/python3.8/site-packages/urllib3/connection.py", line 363, in connect
    self.sock = conn = self._new_conn()
  File "/home/airflow/.local/lib/python3.8/site-packages/urllib3/connection.py", line 186, in _new_conn
    raise NewConnectionError(
urllib3.exceptions.NewConnectionError: <urllib3.connection.HTTPSConnection object at 0x7f106221d790>: Failed to establish a new connection: [Errno -2] Name or service not known

During handling of the above exception, another exception occurred:

Traceback (most recent call last):
  File "/home/airflow/.local/lib/python3.8/site-packages/requests/adapters.py", line 486, in send
    resp = conn.urlopen(
  File "/home/airflow/.local/lib/python3.8/site-packages/urllib3/connectionpool.py", line 799, in urlopen
    retries = retries.increment(
  File "/home/airflow/.local/lib/python3.8/site-packages/urllib3/util/retry.py", line 592, in increment
    raise MaxRetryError(_pool, url, error or ResponseError(cause))
urllib3.exceptions.MaxRetryError: HTTPSConnectionPool(host='api.apilayer.com', port=443): Max retries exceeded with url: //unogs/search/titles/ (Caused by NewConnectionError('<urllib3.connection.HTTPSConnection object at 0x7f106221d790>: Failed to establish a new connection: [Errno -2] Name or service not known'))

During handling of the above exception, another exception occurred:

Traceback (most recent call last):
  File "/home/airflow/.local/lib/python3.8/site-packages/airflow/models/taskinstance.py", line 444, in _execute_task
    result = _execute_callable(context=context, **execute_callable_kwargs)
  File "/home/airflow/.local/lib/python3.8/site-packages/airflow/models/taskinstance.py", line 414, in _execute_callable
    return execute_callable(context=context, **execute_callable_kwargs)
  File "/home/airflow/.local/lib/python3.8/site-packages/airflow/providers/http/operators/http.py", line 166, in execute
    return self.execute_sync(context=context)
  File "/home/airflow/.local/lib/python3.8/site-packages/airflow/providers/http/operators/http.py", line 170, in execute_sync
    response = self.hook.run(self.endpoint, self.data, self.headers, self.extra_options)
  File "/home/airflow/.local/lib/python3.8/site-packages/airflow/providers/http/hooks/http.py", line 180, in run
    return self.run_and_check(session, prepped_request, extra_options)
  File "/home/airflow/.local/lib/python3.8/site-packages/airflow/providers/http/hooks/http.py", line 236, in run_and_check
    raise ex
  File "/home/airflow/.local/lib/python3.8/site-packages/airflow/providers/http/hooks/http.py", line 228, in run_and_check
    response = session.send(prepped_request, **send_kwargs)
  File "/home/airflow/.local/lib/python3.8/site-packages/requests/sessions.py", line 703, in send
    r = adapter.send(request, **kwargs)
  File "/home/airflow/.local/lib/python3.8/site-packages/requests/adapters.py", line 519, in send
    raise ConnectionError(e, request=request)
requests.exceptions.ConnectionError: HTTPSConnectionPool(host='api.apilayer.com', port=443): Max retries exceeded with url: //unogs/search/titles/ (Caused by NewConnectionError('<urllib3.connection.HTTPSConnection object at 0x7f106221d790>: Failed to establish a new connection: [Errno -2] Name or service not known'))
[2024-03-10T01:16:40.019+0000] {taskinstance.py:1149} INFO - Marking task as FAILED. dag_id=netflix_etl_dag, task_id=is_api_available, execution_date=20240309T000000, start_date=20240310T011639, end_date=20240310T011640
[2024-03-10T01:16:40.036+0000] {standard_task_runner.py:107} ERROR - Failed to execute job 11 for task is_api_available (HTTPSConnectionPool(host='api.apilayer.com', port=443): Max retries exceeded with url: //unogs/search/titles/ (Caused by NewConnectionError('<urllib3.connection.HTTPSConnection object at 0x7f106221d790>: Failed to establish a new connection: [Errno -2] Name or service not known')); 1617)
[2024-03-10T01:16:40.067+0000] {local_task_job_runner.py:234} INFO - Task exited with return code 1
[2024-03-10T01:16:40.092+0000] {taskinstance.py:3309} INFO - 0 downstream tasks scheduled from follow-on schedule check
