[2024-03-10T13:37:40.535+0000] {taskinstance.py:1979} INFO - Dependencies all met for dep_context=non-requeueable deps ti=<TaskInstance: netflix_etl_dag.is_api_available manual__2024-03-10T13:16:09.628401+00:00 [queued]>
[2024-03-10T13:37:40.548+0000] {taskinstance.py:1979} INFO - Dependencies all met for dep_context=requeueable deps ti=<TaskInstance: netflix_etl_dag.is_api_available manual__2024-03-10T13:16:09.628401+00:00 [queued]>
[2024-03-10T13:37:40.549+0000] {taskinstance.py:2193} INFO - Starting attempt 2 of 3
[2024-03-10T13:37:40.573+0000] {taskinstance.py:2214} INFO - Executing <Task(HttpSensor): is_api_available> on 2024-03-10 13:16:09.628401+00:00
[2024-03-10T13:37:40.579+0000] {standard_task_runner.py:60} INFO - Started process 125 to run task
[2024-03-10T13:37:40.586+0000] {standard_task_runner.py:87} INFO - Running: ['***', 'tasks', 'run', 'netflix_etl_dag', 'is_api_available', 'manual__2024-03-10T13:16:09.628401+00:00', '--job-id', '31', '--raw', '--subdir', 'DAGS_FOLDER/netflix_dag.py', '--cfg-path', '/tmp/tmpnycow1at']
[2024-03-10T13:37:40.589+0000] {standard_task_runner.py:88} INFO - Job 31: Subtask is_api_available
[2024-03-10T13:37:40.690+0000] {task_command.py:423} INFO - Running <TaskInstance: netflix_etl_dag.is_api_available manual__2024-03-10T13:16:09.628401+00:00 [running]> on host f228308a413a
[2024-03-10T13:37:40.856+0000] {taskinstance.py:2510} INFO - Exporting env vars: AIRFLOW_CTX_DAG_EMAIL='anamsken60@gmail.com' AIRFLOW_CTX_DAG_OWNER='***' AIRFLOW_CTX_DAG_ID='netflix_etl_dag' AIRFLOW_CTX_TASK_ID='is_api_available' AIRFLOW_CTX_EXECUTION_DATE='2024-03-10T13:16:09.628401+00:00' AIRFLOW_CTX_TRY_NUMBER='2' AIRFLOW_CTX_DAG_RUN_ID='manual__2024-03-10T13:16:09.628401+00:00'
[2024-03-10T13:37:40.861+0000] {http.py:137} INFO - Poking: unogs/
[2024-03-10T13:37:40.877+0000] {base.py:83} INFO - Using connection ID 'netflix_api' for task execution.
[2024-03-10T13:37:41.635+0000] {http.py:192} ERROR - HTTP error: Not Found
[2024-03-10T13:37:41.670+0000] {http.py:193} ERROR - {"message":"no Route matched with those values"}
[2024-03-10T13:38:10.983+0000] {local_task_job_runner.py:302} WARNING - State of this instance has been externally set to failed. Terminating instance.
[2024-03-10T13:38:11.017+0000] {process_utils.py:131} INFO - Sending 15 to group 125. PIDs of all processes in the group: [125]
[2024-03-10T13:38:11.019+0000] {process_utils.py:86} INFO - Sending the signal 15 to group 125
[2024-03-10T13:38:11.026+0000] {taskinstance.py:2480} ERROR - Received SIGTERM. Terminating subprocesses.
[2024-03-10T13:38:11.212+0000] {process_utils.py:79} INFO - Process psutil.Process(pid=125, status='terminated', exitcode=0, started='13:37:40') (125) terminated with exit code 0
