[2024-03-10T23:49:42.471+0000] {taskinstance.py:1979} INFO - Dependencies all met for dep_context=non-requeueable deps ti=<TaskInstance: netflix_etl_dag.extract_data_task manual__2024-03-10T23:47:08.402882+00:00 [queued]>
[2024-03-10T23:49:42.481+0000] {taskinstance.py:1979} INFO - Dependencies all met for dep_context=requeueable deps ti=<TaskInstance: netflix_etl_dag.extract_data_task manual__2024-03-10T23:47:08.402882+00:00 [queued]>
[2024-03-10T23:49:42.482+0000] {taskinstance.py:2193} INFO - Starting attempt 2 of 3
[2024-03-10T23:49:42.496+0000] {taskinstance.py:2214} INFO - Executing <Task(PythonOperator): extract_data_task> on 2024-03-10 23:47:08.402882+00:00
[2024-03-10T23:49:42.502+0000] {standard_task_runner.py:60} INFO - Started process 1163 to run task
[2024-03-10T23:49:42.506+0000] {standard_task_runner.py:87} INFO - Running: ['***', 'tasks', 'run', 'netflix_etl_dag', 'extract_data_task', 'manual__2024-03-10T23:47:08.402882+00:00', '--job-id', '72', '--raw', '--subdir', 'DAGS_FOLDER/netflix_dag.py', '--cfg-path', '/tmp/tmppxogacg2']
[2024-03-10T23:49:42.510+0000] {standard_task_runner.py:88} INFO - Job 72: Subtask extract_data_task
[2024-03-10T23:49:42.570+0000] {task_command.py:423} INFO - Running <TaskInstance: netflix_etl_dag.extract_data_task manual__2024-03-10T23:47:08.402882+00:00 [running]> on host 472fedd09e2a
[2024-03-10T23:49:42.675+0000] {taskinstance.py:2510} INFO - Exporting env vars: AIRFLOW_CTX_DAG_EMAIL='anamsken60@gmail.com' AIRFLOW_CTX_DAG_OWNER='***' AIRFLOW_CTX_DAG_ID='netflix_etl_dag' AIRFLOW_CTX_TASK_ID='extract_data_task' AIRFLOW_CTX_EXECUTION_DATE='2024-03-10T23:47:08.402882+00:00' AIRFLOW_CTX_TRY_NUMBER='2' AIRFLOW_CTX_DAG_RUN_ID='manual__2024-03-10T23:47:08.402882+00:00'
[2024-03-10T23:50:16.741+0000] {taskinstance.py:2728} ERROR - Task failed with exception
Traceback (most recent call last):
  File "/home/airflow/.local/lib/python3.8/site-packages/urllib3/connectionpool.py", line 715, in urlopen
    httplib_response = self._make_request(
  File "/home/airflow/.local/lib/python3.8/site-packages/urllib3/connectionpool.py", line 404, in _make_request
    self._validate_conn(conn)
  File "/home/airflow/.local/lib/python3.8/site-packages/urllib3/connectionpool.py", line 1058, in _validate_conn
    conn.connect()
  File "/home/airflow/.local/lib/python3.8/site-packages/urllib3/connection.py", line 419, in connect
    self.sock = ssl_wrap_socket(
  File "/home/airflow/.local/lib/python3.8/site-packages/urllib3/util/ssl_.py", line 449, in ssl_wrap_socket
    ssl_sock = _ssl_wrap_socket_impl(
  File "/home/airflow/.local/lib/python3.8/site-packages/urllib3/util/ssl_.py", line 493, in _ssl_wrap_socket_impl
    return ssl_context.wrap_socket(sock, server_hostname=server_hostname)
  File "/usr/local/lib/python3.8/ssl.py", line 500, in wrap_socket
    return self.sslsocket_class._create(
  File "/usr/local/lib/python3.8/ssl.py", line 1073, in _create
    self.do_handshake()
  File "/usr/local/lib/python3.8/ssl.py", line 1342, in do_handshake
    self._sslobj.do_handshake()
ssl.SSLZeroReturnError: TLS/SSL connection has been closed (EOF) (_ssl.c:1131)

During handling of the above exception, another exception occurred:

Traceback (most recent call last):
  File "/home/airflow/.local/lib/python3.8/site-packages/requests/adapters.py", line 486, in send
    resp = conn.urlopen(
  File "/home/airflow/.local/lib/python3.8/site-packages/urllib3/connectionpool.py", line 799, in urlopen
    retries = retries.increment(
  File "/home/airflow/.local/lib/python3.8/site-packages/urllib3/util/retry.py", line 592, in increment
    raise MaxRetryError(_pool, url, error or ResponseError(cause))
urllib3.exceptions.MaxRetryError: HTTPSConnectionPool(host='api.apilayer.com', port=443): Max retries exceeded with url: /unogs/search/titles?start_year=2024&order_by=date&end_year=2024&limit=100&offset=0 (Caused by SSLError(SSLZeroReturnError(6, 'TLS/SSL connection has been closed (EOF) (_ssl.c:1131)')))

During handling of the above exception, another exception occurred:

Traceback (most recent call last):
  File "/home/airflow/.local/lib/python3.8/site-packages/airflow/models/taskinstance.py", line 444, in _execute_task
    result = _execute_callable(context=context, **execute_callable_kwargs)
  File "/home/airflow/.local/lib/python3.8/site-packages/airflow/models/taskinstance.py", line 414, in _execute_callable
    return execute_callable(context=context, **execute_callable_kwargs)
  File "/home/airflow/.local/lib/python3.8/site-packages/airflow/operators/python.py", line 200, in execute
    return_value = self.execute_callable()
  File "/home/airflow/.local/lib/python3.8/site-packages/airflow/operators/python.py", line 217, in execute_callable
    return self.python_callable(*self.op_args, **self.op_kwargs)
  File "/opt/airflow/dags/netflix_dag.py", line 35, in extract_titles
    response = requests.request("GET", url, headers=headers, data=payload)
  File "/home/airflow/.local/lib/python3.8/site-packages/requests/api.py", line 59, in request
    return session.request(method=method, url=url, **kwargs)
  File "/home/airflow/.local/lib/python3.8/site-packages/requests/sessions.py", line 589, in request
    resp = self.send(prep, **send_kwargs)
  File "/home/airflow/.local/lib/python3.8/site-packages/requests/sessions.py", line 703, in send
    r = adapter.send(request, **kwargs)
  File "/home/airflow/.local/lib/python3.8/site-packages/requests/adapters.py", line 517, in send
    raise SSLError(e, request=request)
requests.exceptions.SSLError: HTTPSConnectionPool(host='api.apilayer.com', port=443): Max retries exceeded with url: /unogs/search/titles?start_year=2024&order_by=date&end_year=2024&limit=100&offset=0 (Caused by SSLError(SSLZeroReturnError(6, 'TLS/SSL connection has been closed (EOF) (_ssl.c:1131)')))
[2024-03-10T23:50:16.762+0000] {taskinstance.py:1149} INFO - Marking task as UP_FOR_RETRY. dag_id=netflix_etl_dag, task_id=extract_data_task, execution_date=20240310T234708, start_date=20240310T234942, end_date=20240310T235016
[2024-03-10T23:50:16.778+0000] {standard_task_runner.py:107} ERROR - Failed to execute job 72 for task extract_data_task (HTTPSConnectionPool(host='api.apilayer.com', port=443): Max retries exceeded with url: /unogs/search/titles?start_year=2024&order_by=date&end_year=2024&limit=100&offset=0 (Caused by SSLError(SSLZeroReturnError(6, 'TLS/SSL connection has been closed (EOF) (_ssl.c:1131)'))); 1163)
[2024-03-10T23:50:16.799+0000] {local_task_job_runner.py:234} INFO - Task exited with return code 1
[2024-03-10T23:50:16.828+0000] {taskinstance.py:3309} INFO - 0 downstream tasks scheduled from follow-on schedule check
