[2024-03-10T15:50:42.702+0000] {taskinstance.py:1979} INFO - Dependencies all met for dep_context=non-requeueable deps ti=<TaskInstance: netflix_etl_dag.extract_data_task manual__2024-03-10T15:48:35.685926+00:00 [queued]>
[2024-03-10T15:50:42.710+0000] {taskinstance.py:1979} INFO - Dependencies all met for dep_context=requeueable deps ti=<TaskInstance: netflix_etl_dag.extract_data_task manual__2024-03-10T15:48:35.685926+00:00 [queued]>
[2024-03-10T15:50:42.711+0000] {taskinstance.py:2193} INFO - Starting attempt 2 of 3
[2024-03-10T15:50:42.724+0000] {taskinstance.py:2214} INFO - Executing <Task(PythonOperator): extract_data_task> on 2024-03-10 15:48:35.685926+00:00
[2024-03-10T15:50:42.729+0000] {standard_task_runner.py:60} INFO - Started process 116 to run task
[2024-03-10T15:50:42.732+0000] {standard_task_runner.py:87} INFO - Running: ['***', 'tasks', 'run', 'netflix_etl_dag', 'extract_data_task', 'manual__2024-03-10T15:48:35.685926+00:00', '--job-id', '62', '--raw', '--subdir', 'DAGS_FOLDER/netflix_dag.py', '--cfg-path', '/tmp/tmpisv1n81j']
[2024-03-10T15:50:42.734+0000] {standard_task_runner.py:88} INFO - Job 62: Subtask extract_data_task
[2024-03-10T15:50:42.780+0000] {task_command.py:423} INFO - Running <TaskInstance: netflix_etl_dag.extract_data_task manual__2024-03-10T15:48:35.685926+00:00 [running]> on host 3a35783bfe2a
[2024-03-10T15:50:42.857+0000] {taskinstance.py:2510} INFO - Exporting env vars: AIRFLOW_CTX_DAG_EMAIL='anamsken60@gmail.com' AIRFLOW_CTX_DAG_OWNER='***' AIRFLOW_CTX_DAG_ID='netflix_etl_dag' AIRFLOW_CTX_TASK_ID='extract_data_task' AIRFLOW_CTX_EXECUTION_DATE='2024-03-10T15:48:35.685926+00:00' AIRFLOW_CTX_TRY_NUMBER='2' AIRFLOW_CTX_DAG_RUN_ID='manual__2024-03-10T15:48:35.685926+00:00'
[2024-03-10T15:50:45.634+0000] {taskinstance.py:2728} ERROR - Task failed with exception
Traceback (most recent call last):
  File "/home/airflow/.local/lib/python3.8/site-packages/airflow/models/taskinstance.py", line 444, in _execute_task
    result = _execute_callable(context=context, **execute_callable_kwargs)
  File "/home/airflow/.local/lib/python3.8/site-packages/airflow/models/taskinstance.py", line 414, in _execute_callable
    return execute_callable(context=context, **execute_callable_kwargs)
  File "/home/airflow/.local/lib/python3.8/site-packages/airflow/operators/python.py", line 200, in execute
    return_value = self.execute_callable()
  File "/home/airflow/.local/lib/python3.8/site-packages/airflow/operators/python.py", line 217, in execute_callable
    return self.python_callable(*self.op_args, **self.op_kwargs)
  File "/opt/airflow/dags/netflix_dag.py", line 37, in extract_titles
    if not data["results"]:
KeyError: 'results'
[2024-03-10T15:50:45.646+0000] {taskinstance.py:1149} INFO - Marking task as UP_FOR_RETRY. dag_id=netflix_etl_dag, task_id=extract_data_task, execution_date=20240310T154835, start_date=20240310T155042, end_date=20240310T155045
[2024-03-10T15:50:45.661+0000] {standard_task_runner.py:107} ERROR - Failed to execute job 62 for task extract_data_task ('results'; 116)
[2024-03-10T15:50:45.669+0000] {local_task_job_runner.py:234} INFO - Task exited with return code 1
[2024-03-10T15:50:45.688+0000] {taskinstance.py:3309} INFO - 0 downstream tasks scheduled from follow-on schedule check
