[2024-03-10T12:49:09.067+0000] {taskinstance.py:1979} INFO - Dependencies all met for dep_context=non-requeueable deps ti=<TaskInstance: netflix_etl_dag.is_api_available manual__2024-03-10T12:44:57.367807+00:00 [queued]>
[2024-03-10T12:49:09.086+0000] {taskinstance.py:1979} INFO - Dependencies all met for dep_context=requeueable deps ti=<TaskInstance: netflix_etl_dag.is_api_available manual__2024-03-10T12:44:57.367807+00:00 [queued]>
[2024-03-10T12:49:09.087+0000] {taskinstance.py:2193} INFO - Starting attempt 3 of 3
[2024-03-10T12:49:09.122+0000] {taskinstance.py:2214} INFO - Executing <Task(HttpSensor): is_api_available> on 2024-03-10 12:44:57.367807+00:00
[2024-03-10T12:49:09.131+0000] {standard_task_runner.py:60} INFO - Started process 195 to run task
[2024-03-10T12:49:09.138+0000] {standard_task_runner.py:87} INFO - Running: ['***', 'tasks', 'run', 'netflix_etl_dag', 'is_api_available', 'manual__2024-03-10T12:44:57.367807+00:00', '--job-id', '20', '--raw', '--subdir', 'DAGS_FOLDER/netflix_dag.py', '--cfg-path', '/tmp/tmp6yakplf6']
[2024-03-10T12:49:09.143+0000] {standard_task_runner.py:88} INFO - Job 20: Subtask is_api_available
[2024-03-10T12:49:09.237+0000] {task_command.py:423} INFO - Running <TaskInstance: netflix_etl_dag.is_api_available manual__2024-03-10T12:44:57.367807+00:00 [running]> on host aaa4b1109113
[2024-03-10T12:49:09.587+0000] {taskinstance.py:2510} INFO - Exporting env vars: AIRFLOW_CTX_DAG_EMAIL='anamsken60@gmail.com' AIRFLOW_CTX_DAG_OWNER='***' AIRFLOW_CTX_DAG_ID='netflix_etl_dag' AIRFLOW_CTX_TASK_ID='is_api_available' AIRFLOW_CTX_EXECUTION_DATE='2024-03-10T12:44:57.367807+00:00' AIRFLOW_CTX_TRY_NUMBER='3' AIRFLOW_CTX_DAG_RUN_ID='manual__2024-03-10T12:44:57.367807+00:00'
[2024-03-10T12:49:09.590+0000] {http.py:137} INFO - Poking: /search/titles/
[2024-03-10T12:49:09.607+0000] {base.py:83} INFO - Using connection ID 'netflix_api' for task execution.
[2024-03-10T12:49:10.606+0000] {http.py:192} ERROR - HTTP error: Not Found
[2024-03-10T12:49:10.636+0000] {http.py:193} ERROR - {"message":"no Route matched with those values"}
[2024-03-10T12:50:10.656+0000] {http.py:137} INFO - Poking: /search/titles/
[2024-03-10T12:50:10.694+0000] {base.py:83} INFO - Using connection ID 'netflix_api' for task execution.
[2024-03-10T12:50:11.931+0000] {http.py:192} ERROR - HTTP error: Not Found
[2024-03-10T12:50:11.945+0000] {http.py:193} ERROR - {"message":"no Route matched with those values"}
[2024-03-10T12:51:12.040+0000] {http.py:137} INFO - Poking: /search/titles/
[2024-03-10T12:51:12.052+0000] {base.py:83} INFO - Using connection ID 'netflix_api' for task execution.
[2024-03-10T12:51:13.147+0000] {http.py:192} ERROR - HTTP error: Not Found
[2024-03-10T12:51:13.148+0000] {http.py:193} ERROR - {"message":"no Route matched with those values"}
[2024-03-10T12:52:13.176+0000] {http.py:137} INFO - Poking: /search/titles/
[2024-03-10T12:52:13.187+0000] {base.py:83} INFO - Using connection ID 'netflix_api' for task execution.
[2024-03-10T12:52:14.187+0000] {http.py:192} ERROR - HTTP error: Not Found
[2024-03-10T12:52:14.188+0000] {http.py:193} ERROR - {"message":"no Route matched with those values"}
[2024-03-10T12:53:14.214+0000] {http.py:137} INFO - Poking: /search/titles/
[2024-03-10T12:53:14.224+0000] {base.py:83} INFO - Using connection ID 'netflix_api' for task execution.
[2024-03-10T12:53:15.771+0000] {http.py:192} ERROR - HTTP error: Not Found
[2024-03-10T12:53:15.772+0000] {http.py:193} ERROR - {"message":"no Route matched with those values"}
[2024-03-10T12:54:15.821+0000] {http.py:137} INFO - Poking: /search/titles/
[2024-03-10T12:54:15.832+0000] {base.py:83} INFO - Using connection ID 'netflix_api' for task execution.
[2024-03-10T12:54:16.604+0000] {http.py:192} ERROR - HTTP error: Not Found
[2024-03-10T12:54:16.605+0000] {http.py:193} ERROR - {"message":"no Route matched with those values"}
[2024-03-10T12:55:16.618+0000] {http.py:137} INFO - Poking: /search/titles/
[2024-03-10T12:55:16.628+0000] {base.py:83} INFO - Using connection ID 'netflix_api' for task execution.
[2024-03-10T12:55:18.206+0000] {http.py:192} ERROR - HTTP error: Not Found
[2024-03-10T12:55:18.207+0000] {http.py:193} ERROR - {"message":"no Route matched with those values"}
[2024-03-10T12:56:18.238+0000] {http.py:137} INFO - Poking: /search/titles/
[2024-03-10T12:56:18.246+0000] {base.py:83} INFO - Using connection ID 'netflix_api' for task execution.
[2024-03-10T12:56:19.382+0000] {http.py:192} ERROR - HTTP error: Not Found
[2024-03-10T12:56:19.383+0000] {http.py:193} ERROR - {"message":"no Route matched with those values"}
[2024-03-10T12:57:19.497+0000] {http.py:137} INFO - Poking: /search/titles/
[2024-03-10T12:57:19.506+0000] {base.py:83} INFO - Using connection ID 'netflix_api' for task execution.
[2024-03-10T12:57:19.513+0000] {http.py:235} WARNING - HTTPSConnectionPool(host='api.apilayer.com', port=443): Max retries exceeded with url: /unogs//search/titles/ (Caused by NewConnectionError('<urllib3.connection.HTTPSConnection object at 0x7f9308d049a0>: Failed to establish a new connection: [Errno -2] Name or service not known')) Tenacity will retry to execute the operation
[2024-03-10T12:57:19.514+0000] {taskinstance.py:2728} ERROR - Task failed with exception
Traceback (most recent call last):
  File "/home/airflow/.local/lib/python3.8/site-packages/urllib3/connection.py", line 174, in _new_conn
    conn = connection.create_connection(
  File "/home/airflow/.local/lib/python3.8/site-packages/urllib3/util/connection.py", line 72, in create_connection
    for res in socket.getaddrinfo(host, port, family, socket.SOCK_STREAM):
  File "/usr/local/lib/python3.8/socket.py", line 918, in getaddrinfo
    for res in _socket.getaddrinfo(host, port, family, type, proto, flags):
socket.gaierror: [Errno -2] Name or service not known

During handling of the above exception, another exception occurred:

Traceback (most recent call last):
  File "/home/airflow/.local/lib/python3.8/site-packages/urllib3/connectionpool.py", line 715, in urlopen
    httplib_response = self._make_request(
  File "/home/airflow/.local/lib/python3.8/site-packages/urllib3/connectionpool.py", line 404, in _make_request
    self._validate_conn(conn)
  File "/home/airflow/.local/lib/python3.8/site-packages/urllib3/connectionpool.py", line 1058, in _validate_conn
    conn.connect()
  File "/home/airflow/.local/lib/python3.8/site-packages/urllib3/connection.py", line 363, in connect
    self.sock = conn = self._new_conn()
  File "/home/airflow/.local/lib/python3.8/site-packages/urllib3/connection.py", line 186, in _new_conn
    raise NewConnectionError(
urllib3.exceptions.NewConnectionError: <urllib3.connection.HTTPSConnection object at 0x7f9308d049a0>: Failed to establish a new connection: [Errno -2] Name or service not known

During handling of the above exception, another exception occurred:

Traceback (most recent call last):
  File "/home/airflow/.local/lib/python3.8/site-packages/requests/adapters.py", line 486, in send
    resp = conn.urlopen(
  File "/home/airflow/.local/lib/python3.8/site-packages/urllib3/connectionpool.py", line 799, in urlopen
    retries = retries.increment(
  File "/home/airflow/.local/lib/python3.8/site-packages/urllib3/util/retry.py", line 592, in increment
    raise MaxRetryError(_pool, url, error or ResponseError(cause))
urllib3.exceptions.MaxRetryError: HTTPSConnectionPool(host='api.apilayer.com', port=443): Max retries exceeded with url: /unogs//search/titles/ (Caused by NewConnectionError('<urllib3.connection.HTTPSConnection object at 0x7f9308d049a0>: Failed to establish a new connection: [Errno -2] Name or service not known'))

During handling of the above exception, another exception occurred:

Traceback (most recent call last):
  File "/home/airflow/.local/lib/python3.8/site-packages/airflow/models/taskinstance.py", line 444, in _execute_task
    result = _execute_callable(context=context, **execute_callable_kwargs)
  File "/home/airflow/.local/lib/python3.8/site-packages/airflow/models/taskinstance.py", line 414, in _execute_callable
    return execute_callable(context=context, **execute_callable_kwargs)
  File "/home/airflow/.local/lib/python3.8/site-packages/airflow/providers/http/sensors/http.py", line 164, in execute
    super().execute(context=context)
  File "/home/airflow/.local/lib/python3.8/site-packages/airflow/sensors/base.py", line 265, in execute
    raise e
  File "/home/airflow/.local/lib/python3.8/site-packages/airflow/sensors/base.py", line 247, in execute
    poke_return = self.poke(context)
  File "/home/airflow/.local/lib/python3.8/site-packages/airflow/providers/http/sensors/http.py", line 139, in poke
    response = hook.run(
  File "/home/airflow/.local/lib/python3.8/site-packages/airflow/providers/http/hooks/http.py", line 180, in run
    return self.run_and_check(session, prepped_request, extra_options)
  File "/home/airflow/.local/lib/python3.8/site-packages/airflow/providers/http/hooks/http.py", line 236, in run_and_check
    raise ex
  File "/home/airflow/.local/lib/python3.8/site-packages/airflow/providers/http/hooks/http.py", line 228, in run_and_check
    response = session.send(prepped_request, **send_kwargs)
  File "/home/airflow/.local/lib/python3.8/site-packages/requests/sessions.py", line 703, in send
    r = adapter.send(request, **kwargs)
  File "/home/airflow/.local/lib/python3.8/site-packages/requests/adapters.py", line 519, in send
    raise ConnectionError(e, request=request)
requests.exceptions.ConnectionError: HTTPSConnectionPool(host='api.apilayer.com', port=443): Max retries exceeded with url: /unogs//search/titles/ (Caused by NewConnectionError('<urllib3.connection.HTTPSConnection object at 0x7f9308d049a0>: Failed to establish a new connection: [Errno -2] Name or service not known'))
[2024-03-10T12:57:19.526+0000] {taskinstance.py:1149} INFO - Marking task as FAILED. dag_id=netflix_etl_dag, task_id=is_api_available, execution_date=20240310T124457, start_date=20240310T124909, end_date=20240310T125719
[2024-03-10T12:57:19.539+0000] {standard_task_runner.py:107} ERROR - Failed to execute job 20 for task is_api_available (HTTPSConnectionPool(host='api.apilayer.com', port=443): Max retries exceeded with url: /unogs//search/titles/ (Caused by NewConnectionError('<urllib3.connection.HTTPSConnection object at 0x7f9308d049a0>: Failed to establish a new connection: [Errno -2] Name or service not known')); 195)
[2024-03-10T12:57:19.554+0000] {local_task_job_runner.py:234} INFO - Task exited with return code 1
[2024-03-10T12:57:19.572+0000] {taskinstance.py:3309} INFO - 0 downstream tasks scheduled from follow-on schedule check
