[2024-03-10T13:38:12.347+0000] {taskinstance.py:1979} INFO - Dependencies all met for dep_context=non-requeueable deps ti=<TaskInstance: netflix_etl_dag.is_api_available manual__2024-03-10T13:38:09.479645+00:00 [queued]>
[2024-03-10T13:38:12.362+0000] {taskinstance.py:1979} INFO - Dependencies all met for dep_context=requeueable deps ti=<TaskInstance: netflix_etl_dag.is_api_available manual__2024-03-10T13:38:09.479645+00:00 [queued]>
[2024-03-10T13:38:12.362+0000] {taskinstance.py:2193} INFO - Starting attempt 1 of 3
[2024-03-10T13:38:12.380+0000] {taskinstance.py:2214} INFO - Executing <Task(HttpSensor): is_api_available> on 2024-03-10 13:38:09.479645+00:00
[2024-03-10T13:38:12.387+0000] {standard_task_runner.py:60} INFO - Started process 127 to run task
[2024-03-10T13:38:12.393+0000] {standard_task_runner.py:87} INFO - Running: ['***', 'tasks', 'run', 'netflix_etl_dag', 'is_api_available', 'manual__2024-03-10T13:38:09.479645+00:00', '--job-id', '32', '--raw', '--subdir', 'DAGS_FOLDER/netflix_dag.py', '--cfg-path', '/tmp/tmpeea1pp4p']
[2024-03-10T13:38:12.396+0000] {standard_task_runner.py:88} INFO - Job 32: Subtask is_api_available
[2024-03-10T13:38:12.502+0000] {task_command.py:423} INFO - Running <TaskInstance: netflix_etl_dag.is_api_available manual__2024-03-10T13:38:09.479645+00:00 [running]> on host f228308a413a
[2024-03-10T13:38:12.716+0000] {taskinstance.py:2510} INFO - Exporting env vars: AIRFLOW_CTX_DAG_EMAIL='anamsken60@gmail.com' AIRFLOW_CTX_DAG_OWNER='***' AIRFLOW_CTX_DAG_ID='netflix_etl_dag' AIRFLOW_CTX_TASK_ID='is_api_available' AIRFLOW_CTX_EXECUTION_DATE='2024-03-10T13:38:09.479645+00:00' AIRFLOW_CTX_TRY_NUMBER='1' AIRFLOW_CTX_DAG_RUN_ID='manual__2024-03-10T13:38:09.479645+00:00'
[2024-03-10T13:38:12.721+0000] {http.py:137} INFO - Poking: unogs/
[2024-03-10T13:38:12.778+0000] {base.py:83} INFO - Using connection ID 'netflix_api' for task execution.
[2024-03-10T13:38:13.630+0000] {http.py:192} ERROR - HTTP error: Not Found
[2024-03-10T13:38:13.633+0000] {http.py:193} ERROR - {"message":"no Route matched with those values"}
[2024-03-10T13:39:13.679+0000] {http.py:137} INFO - Poking: unogs/
[2024-03-10T13:39:13.727+0000] {base.py:83} INFO - Using connection ID 'netflix_api' for task execution.
[2024-03-10T13:39:15.023+0000] {http.py:192} ERROR - HTTP error: Not Found
[2024-03-10T13:39:15.024+0000] {http.py:193} ERROR - {"message":"no Route matched with those values"}
[2024-03-10T13:40:15.063+0000] {http.py:137} INFO - Poking: unogs/
[2024-03-10T13:40:15.079+0000] {base.py:83} INFO - Using connection ID 'netflix_api' for task execution.
[2024-03-10T13:40:16.235+0000] {http.py:192} ERROR - HTTP error: Not Found
[2024-03-10T13:40:16.240+0000] {http.py:193} ERROR - {"message":"no Route matched with those values"}
[2024-03-10T13:41:16.290+0000] {http.py:137} INFO - Poking: unogs/
[2024-03-10T13:41:16.300+0000] {base.py:83} INFO - Using connection ID 'netflix_api' for task execution.
[2024-03-10T13:41:27.779+0000] {http.py:192} ERROR - HTTP error: Not Found
[2024-03-10T13:41:27.781+0000] {http.py:193} ERROR - {"message":"no Route matched with those values"}
[2024-03-10T13:42:27.834+0000] {http.py:137} INFO - Poking: unogs/
[2024-03-10T13:42:27.846+0000] {base.py:83} INFO - Using connection ID 'netflix_api' for task execution.
[2024-03-10T13:42:28.880+0000] {http.py:192} ERROR - HTTP error: Not Found
[2024-03-10T13:42:28.882+0000] {http.py:193} ERROR - {"message":"no Route matched with those values"}
[2024-03-10T13:43:28.887+0000] {http.py:137} INFO - Poking: unogs/
[2024-03-10T13:43:28.903+0000] {base.py:83} INFO - Using connection ID 'netflix_api' for task execution.
[2024-03-10T13:43:29.984+0000] {http.py:192} ERROR - HTTP error: Not Found
[2024-03-10T13:43:29.986+0000] {http.py:193} ERROR - {"message":"no Route matched with those values"}
[2024-03-10T13:44:30.041+0000] {http.py:137} INFO - Poking: unogs/
[2024-03-10T13:44:30.056+0000] {base.py:83} INFO - Using connection ID 'netflix_api' for task execution.
[2024-03-10T13:44:40.143+0000] {http.py:192} ERROR - HTTP error: Not Found
[2024-03-10T13:44:40.147+0000] {http.py:193} ERROR - {"message":"no Route matched with those values"}
[2024-03-10T13:45:40.204+0000] {http.py:137} INFO - Poking: unogs/
[2024-03-10T13:45:40.219+0000] {base.py:83} INFO - Using connection ID 'netflix_api' for task execution.
[2024-03-10T13:45:40.963+0000] {http.py:192} ERROR - HTTP error: Not Found
[2024-03-10T13:45:40.966+0000] {http.py:193} ERROR - {"message":"no Route matched with those values"}
[2024-03-10T13:46:40.992+0000] {http.py:137} INFO - Poking: unogs/
[2024-03-10T13:46:41.014+0000] {base.py:83} INFO - Using connection ID 'netflix_api' for task execution.
[2024-03-10T13:46:41.885+0000] {http.py:192} ERROR - HTTP error: Not Found
[2024-03-10T13:46:41.886+0000] {http.py:193} ERROR - {"message":"no Route matched with those values"}
[2024-03-10T13:47:41.938+0000] {http.py:137} INFO - Poking: unogs/
[2024-03-10T13:47:41.968+0000] {base.py:83} INFO - Using connection ID 'netflix_api' for task execution.
[2024-03-10T13:47:43.150+0000] {http.py:192} ERROR - HTTP error: Not Found
[2024-03-10T13:47:43.153+0000] {http.py:193} ERROR - {"message":"no Route matched with those values"}
[2024-03-10T13:48:43.216+0000] {http.py:137} INFO - Poking: unogs/
[2024-03-10T13:48:43.228+0000] {base.py:83} INFO - Using connection ID 'netflix_api' for task execution.
[2024-03-10T13:48:43.237+0000] {http.py:235} WARNING - HTTPSConnectionPool(host='api.apilayer.com', port=443): Max retries exceeded with url: /unogs/unogs/ (Caused by NewConnectionError('<urllib3.connection.HTTPSConnection object at 0x7f7f4e9776d0>: Failed to establish a new connection: [Errno -2] Name or service not known')) Tenacity will retry to execute the operation
[2024-03-10T13:48:43.238+0000] {taskinstance.py:2728} ERROR - Task failed with exception
Traceback (most recent call last):
  File "/home/airflow/.local/lib/python3.8/site-packages/urllib3/connection.py", line 174, in _new_conn
    conn = connection.create_connection(
  File "/home/airflow/.local/lib/python3.8/site-packages/urllib3/util/connection.py", line 72, in create_connection
    for res in socket.getaddrinfo(host, port, family, socket.SOCK_STREAM):
  File "/usr/local/lib/python3.8/socket.py", line 918, in getaddrinfo
    for res in _socket.getaddrinfo(host, port, family, type, proto, flags):
socket.gaierror: [Errno -2] Name or service not known

During handling of the above exception, another exception occurred:

Traceback (most recent call last):
  File "/home/airflow/.local/lib/python3.8/site-packages/urllib3/connectionpool.py", line 715, in urlopen
    httplib_response = self._make_request(
  File "/home/airflow/.local/lib/python3.8/site-packages/urllib3/connectionpool.py", line 404, in _make_request
    self._validate_conn(conn)
  File "/home/airflow/.local/lib/python3.8/site-packages/urllib3/connectionpool.py", line 1058, in _validate_conn
    conn.connect()
  File "/home/airflow/.local/lib/python3.8/site-packages/urllib3/connection.py", line 363, in connect
    self.sock = conn = self._new_conn()
  File "/home/airflow/.local/lib/python3.8/site-packages/urllib3/connection.py", line 186, in _new_conn
    raise NewConnectionError(
urllib3.exceptions.NewConnectionError: <urllib3.connection.HTTPSConnection object at 0x7f7f4e9776d0>: Failed to establish a new connection: [Errno -2] Name or service not known

During handling of the above exception, another exception occurred:

Traceback (most recent call last):
  File "/home/airflow/.local/lib/python3.8/site-packages/requests/adapters.py", line 486, in send
    resp = conn.urlopen(
  File "/home/airflow/.local/lib/python3.8/site-packages/urllib3/connectionpool.py", line 799, in urlopen
    retries = retries.increment(
  File "/home/airflow/.local/lib/python3.8/site-packages/urllib3/util/retry.py", line 592, in increment
    raise MaxRetryError(_pool, url, error or ResponseError(cause))
urllib3.exceptions.MaxRetryError: HTTPSConnectionPool(host='api.apilayer.com', port=443): Max retries exceeded with url: /unogs/unogs/ (Caused by NewConnectionError('<urllib3.connection.HTTPSConnection object at 0x7f7f4e9776d0>: Failed to establish a new connection: [Errno -2] Name or service not known'))

During handling of the above exception, another exception occurred:

Traceback (most recent call last):
  File "/home/airflow/.local/lib/python3.8/site-packages/airflow/models/taskinstance.py", line 444, in _execute_task
    result = _execute_callable(context=context, **execute_callable_kwargs)
  File "/home/airflow/.local/lib/python3.8/site-packages/airflow/models/taskinstance.py", line 414, in _execute_callable
    return execute_callable(context=context, **execute_callable_kwargs)
  File "/home/airflow/.local/lib/python3.8/site-packages/airflow/providers/http/sensors/http.py", line 164, in execute
    super().execute(context=context)
  File "/home/airflow/.local/lib/python3.8/site-packages/airflow/sensors/base.py", line 265, in execute
    raise e
  File "/home/airflow/.local/lib/python3.8/site-packages/airflow/sensors/base.py", line 247, in execute
    poke_return = self.poke(context)
  File "/home/airflow/.local/lib/python3.8/site-packages/airflow/providers/http/sensors/http.py", line 139, in poke
    response = hook.run(
  File "/home/airflow/.local/lib/python3.8/site-packages/airflow/providers/http/hooks/http.py", line 180, in run
    return self.run_and_check(session, prepped_request, extra_options)
  File "/home/airflow/.local/lib/python3.8/site-packages/airflow/providers/http/hooks/http.py", line 236, in run_and_check
    raise ex
  File "/home/airflow/.local/lib/python3.8/site-packages/airflow/providers/http/hooks/http.py", line 228, in run_and_check
    response = session.send(prepped_request, **send_kwargs)
  File "/home/airflow/.local/lib/python3.8/site-packages/requests/sessions.py", line 703, in send
    r = adapter.send(request, **kwargs)
  File "/home/airflow/.local/lib/python3.8/site-packages/requests/adapters.py", line 519, in send
    raise ConnectionError(e, request=request)
requests.exceptions.ConnectionError: HTTPSConnectionPool(host='api.apilayer.com', port=443): Max retries exceeded with url: /unogs/unogs/ (Caused by NewConnectionError('<urllib3.connection.HTTPSConnection object at 0x7f7f4e9776d0>: Failed to establish a new connection: [Errno -2] Name or service not known'))
[2024-03-10T13:48:43.249+0000] {taskinstance.py:1149} INFO - Marking task as UP_FOR_RETRY. dag_id=netflix_etl_dag, task_id=is_api_available, execution_date=20240310T133809, start_date=20240310T133812, end_date=20240310T134843
[2024-03-10T13:48:43.265+0000] {standard_task_runner.py:107} ERROR - Failed to execute job 32 for task is_api_available (HTTPSConnectionPool(host='api.apilayer.com', port=443): Max retries exceeded with url: /unogs/unogs/ (Caused by NewConnectionError('<urllib3.connection.HTTPSConnection object at 0x7f7f4e9776d0>: Failed to establish a new connection: [Errno -2] Name or service not known')); 127)
[2024-03-10T13:48:43.297+0000] {local_task_job_runner.py:234} INFO - Task exited with return code 1
[2024-03-10T13:48:43.315+0000] {taskinstance.py:3309} INFO - 0 downstream tasks scheduled from follow-on schedule check
