[2024-03-10T14:29:16.501+0000] {taskinstance.py:1979} INFO - Dependencies all met for dep_context=non-requeueable deps ti=<TaskInstance: netflix_etl_dag.is_api_available manual__2024-03-10T14:29:12.868914+00:00 [queued]>
[2024-03-10T14:29:16.512+0000] {taskinstance.py:1979} INFO - Dependencies all met for dep_context=requeueable deps ti=<TaskInstance: netflix_etl_dag.is_api_available manual__2024-03-10T14:29:12.868914+00:00 [queued]>
[2024-03-10T14:29:16.513+0000] {taskinstance.py:2193} INFO - Starting attempt 1 of 3
[2024-03-10T14:29:16.531+0000] {taskinstance.py:2214} INFO - Executing <Task(HttpSensor): is_api_available> on 2024-03-10 14:29:12.868914+00:00
[2024-03-10T14:29:16.536+0000] {standard_task_runner.py:60} INFO - Started process 249 to run task
[2024-03-10T14:29:16.541+0000] {standard_task_runner.py:87} INFO - Running: ['***', 'tasks', 'run', 'netflix_etl_dag', 'is_api_available', 'manual__2024-03-10T14:29:12.868914+00:00', '--job-id', '46', '--raw', '--subdir', 'DAGS_FOLDER/netflix_dag.py', '--cfg-path', '/tmp/tmpmgrop9z2']
[2024-03-10T14:29:16.543+0000] {standard_task_runner.py:88} INFO - Job 46: Subtask is_api_available
[2024-03-10T14:29:16.603+0000] {task_command.py:423} INFO - Running <TaskInstance: netflix_etl_dag.is_api_available manual__2024-03-10T14:29:12.868914+00:00 [running]> on host ccbdacf6e9da
[2024-03-10T14:29:16.706+0000] {taskinstance.py:2510} INFO - Exporting env vars: AIRFLOW_CTX_DAG_EMAIL='anamsken60@gmail.com' AIRFLOW_CTX_DAG_OWNER='***' AIRFLOW_CTX_DAG_ID='netflix_etl_dag' AIRFLOW_CTX_TASK_ID='is_api_available' AIRFLOW_CTX_EXECUTION_DATE='2024-03-10T14:29:12.868914+00:00' AIRFLOW_CTX_TRY_NUMBER='1' AIRFLOW_CTX_DAG_RUN_ID='manual__2024-03-10T14:29:12.868914+00:00'
[2024-03-10T14:29:16.708+0000] {http.py:137} INFO - Poking: unogs/search/titles
[2024-03-10T14:29:16.722+0000] {base.py:83} INFO - Using connection ID 'netflix_api' for task execution.
[2024-03-10T14:29:17.628+0000] {http.py:192} ERROR - HTTP error: Unauthorized
[2024-03-10T14:29:17.629+0000] {http.py:193} ERROR - {"message":"No API key found in request"}
[2024-03-10T14:29:17.646+0000] {taskinstance.py:2728} ERROR - Task failed with exception
Traceback (most recent call last):
  File "/home/airflow/.local/lib/python3.8/site-packages/airflow/providers/http/hooks/http.py", line 190, in check_response
    response.raise_for_status()
  File "/home/airflow/.local/lib/python3.8/site-packages/requests/models.py", line 1021, in raise_for_status
    raise HTTPError(http_error_msg, response=self)
requests.exceptions.HTTPError: 401 Client Error: Unauthorized for url: https://api.apilayer.com/unogs/search/titles

During handling of the above exception, another exception occurred:

Traceback (most recent call last):
  File "/home/airflow/.local/lib/python3.8/site-packages/airflow/models/taskinstance.py", line 444, in _execute_task
    result = _execute_callable(context=context, **execute_callable_kwargs)
  File "/home/airflow/.local/lib/python3.8/site-packages/airflow/models/taskinstance.py", line 414, in _execute_callable
    return execute_callable(context=context, **execute_callable_kwargs)
  File "/home/airflow/.local/lib/python3.8/site-packages/airflow/providers/http/sensors/http.py", line 164, in execute
    super().execute(context=context)
  File "/home/airflow/.local/lib/python3.8/site-packages/airflow/sensors/base.py", line 265, in execute
    raise e
  File "/home/airflow/.local/lib/python3.8/site-packages/airflow/sensors/base.py", line 247, in execute
    poke_return = self.poke(context)
  File "/home/airflow/.local/lib/python3.8/site-packages/airflow/providers/http/sensors/http.py", line 158, in poke
    raise exc
  File "/home/airflow/.local/lib/python3.8/site-packages/airflow/providers/http/sensors/http.py", line 139, in poke
    response = hook.run(
  File "/home/airflow/.local/lib/python3.8/site-packages/airflow/providers/http/hooks/http.py", line 180, in run
    return self.run_and_check(session, prepped_request, extra_options)
  File "/home/airflow/.local/lib/python3.8/site-packages/airflow/providers/http/hooks/http.py", line 231, in run_and_check
    self.check_response(response)
  File "/home/airflow/.local/lib/python3.8/site-packages/airflow/providers/http/hooks/http.py", line 194, in check_response
    raise AirflowException(str(response.status_code) + ":" + response.reason)
airflow.exceptions.AirflowException: 401:Unauthorized
[2024-03-10T14:29:17.650+0000] {taskinstance.py:1149} INFO - Marking task as UP_FOR_RETRY. dag_id=netflix_etl_dag, task_id=is_api_available, execution_date=20240310T142912, start_date=20240310T142916, end_date=20240310T142917
[2024-03-10T14:29:17.670+0000] {standard_task_runner.py:107} ERROR - Failed to execute job 46 for task is_api_available (401:Unauthorized; 249)
[2024-03-10T14:29:17.710+0000] {local_task_job_runner.py:234} INFO - Task exited with return code 1
[2024-03-10T14:29:17.733+0000] {taskinstance.py:3309} INFO - 0 downstream tasks scheduled from follow-on schedule check
