[2024-03-10T22:13:33.344+0000] {taskinstance.py:1979} INFO - Dependencies all met for dep_context=non-requeueable deps ti=<TaskInstance: netflix_etl_dag.extract_data_task manual__2024-03-10T22:09:19.851549+00:00 [queued]>
[2024-03-10T22:13:33.359+0000] {taskinstance.py:1979} INFO - Dependencies all met for dep_context=requeueable deps ti=<TaskInstance: netflix_etl_dag.extract_data_task manual__2024-03-10T22:09:19.851549+00:00 [queued]>
[2024-03-10T22:13:33.360+0000] {taskinstance.py:2193} INFO - Starting attempt 3 of 3
[2024-03-10T22:13:33.378+0000] {taskinstance.py:2214} INFO - Executing <Task(PythonOperator): extract_data_task> on 2024-03-10 22:09:19.851549+00:00
[2024-03-10T22:13:33.385+0000] {standard_task_runner.py:60} INFO - Started process 317 to run task
[2024-03-10T22:13:33.391+0000] {standard_task_runner.py:87} INFO - Running: ['***', 'tasks', 'run', 'netflix_etl_dag', 'extract_data_task', 'manual__2024-03-10T22:09:19.851549+00:00', '--job-id', '68', '--raw', '--subdir', 'DAGS_FOLDER/netflix_dag.py', '--cfg-path', '/tmp/tmpbkahk2eg']
[2024-03-10T22:13:33.394+0000] {standard_task_runner.py:88} INFO - Job 68: Subtask extract_data_task
[2024-03-10T22:13:33.470+0000] {task_command.py:423} INFO - Running <TaskInstance: netflix_etl_dag.extract_data_task manual__2024-03-10T22:09:19.851549+00:00 [running]> on host 3a35783bfe2a
[2024-03-10T22:13:33.581+0000] {taskinstance.py:2510} INFO - Exporting env vars: AIRFLOW_CTX_DAG_EMAIL='anamsken60@gmail.com' AIRFLOW_CTX_DAG_OWNER='***' AIRFLOW_CTX_DAG_ID='netflix_etl_dag' AIRFLOW_CTX_TASK_ID='extract_data_task' AIRFLOW_CTX_EXECUTION_DATE='2024-03-10T22:09:19.851549+00:00' AIRFLOW_CTX_TRY_NUMBER='3' AIRFLOW_CTX_DAG_RUN_ID='manual__2024-03-10T22:09:19.851549+00:00'
[2024-03-10T22:13:34.511+0000] {taskinstance.py:2728} ERROR - Task failed with exception
Traceback (most recent call last):
  File "/home/airflow/.local/lib/python3.8/site-packages/airflow/models/taskinstance.py", line 444, in _execute_task
    result = _execute_callable(context=context, **execute_callable_kwargs)
  File "/home/airflow/.local/lib/python3.8/site-packages/airflow/models/taskinstance.py", line 414, in _execute_callable
    return execute_callable(context=context, **execute_callable_kwargs)
  File "/home/airflow/.local/lib/python3.8/site-packages/airflow/operators/python.py", line 200, in execute
    return_value = self.execute_callable()
  File "/home/airflow/.local/lib/python3.8/site-packages/airflow/operators/python.py", line 217, in execute_callable
    return self.python_callable(*self.op_args, **self.op_kwargs)
  File "/opt/airflow/dags/netflix_dag.py", line 38, in extract_titles
    if not data["results"]:
KeyError: 'results'
[2024-03-10T22:13:34.561+0000] {taskinstance.py:1149} INFO - Marking task as FAILED. dag_id=netflix_etl_dag, task_id=extract_data_task, execution_date=20240310T220919, start_date=20240310T221333, end_date=20240310T221334
[2024-03-10T22:13:34.589+0000] {standard_task_runner.py:107} ERROR - Failed to execute job 68 for task extract_data_task ('results'; 317)
[2024-03-10T22:13:34.706+0000] {local_task_job_runner.py:234} INFO - Task exited with return code 1
[2024-03-10T22:13:34.777+0000] {taskinstance.py:3309} INFO - 0 downstream tasks scheduled from follow-on schedule check
