[2024-03-10T22:09:24.766+0000] {taskinstance.py:1979} INFO - Dependencies all met for dep_context=non-requeueable deps ti=<TaskInstance: netflix_etl_dag.extract_data_task manual__2024-03-10T22:09:19.851549+00:00 [queued]>
[2024-03-10T22:09:24.778+0000] {taskinstance.py:1979} INFO - Dependencies all met for dep_context=requeueable deps ti=<TaskInstance: netflix_etl_dag.extract_data_task manual__2024-03-10T22:09:19.851549+00:00 [queued]>
[2024-03-10T22:09:24.779+0000] {taskinstance.py:2193} INFO - Starting attempt 1 of 3
[2024-03-10T22:09:24.796+0000] {taskinstance.py:2214} INFO - Executing <Task(PythonOperator): extract_data_task> on 2024-03-10 22:09:19.851549+00:00
[2024-03-10T22:09:24.805+0000] {standard_task_runner.py:60} INFO - Started process 256 to run task
[2024-03-10T22:09:24.812+0000] {standard_task_runner.py:87} INFO - Running: ['***', 'tasks', 'run', 'netflix_etl_dag', 'extract_data_task', 'manual__2024-03-10T22:09:19.851549+00:00', '--job-id', '66', '--raw', '--subdir', 'DAGS_FOLDER/netflix_dag.py', '--cfg-path', '/tmp/tmp5xsa7s4y']
[2024-03-10T22:09:24.819+0000] {standard_task_runner.py:88} INFO - Job 66: Subtask extract_data_task
[2024-03-10T22:09:24.919+0000] {task_command.py:423} INFO - Running <TaskInstance: netflix_etl_dag.extract_data_task manual__2024-03-10T22:09:19.851549+00:00 [running]> on host 3a35783bfe2a
[2024-03-10T22:09:25.049+0000] {taskinstance.py:2510} INFO - Exporting env vars: AIRFLOW_CTX_DAG_EMAIL='anamsken60@gmail.com' AIRFLOW_CTX_DAG_OWNER='***' AIRFLOW_CTX_DAG_ID='netflix_etl_dag' AIRFLOW_CTX_TASK_ID='extract_data_task' AIRFLOW_CTX_EXECUTION_DATE='2024-03-10T22:09:19.851549+00:00' AIRFLOW_CTX_TRY_NUMBER='1' AIRFLOW_CTX_DAG_RUN_ID='manual__2024-03-10T22:09:19.851549+00:00'
[2024-03-10T22:09:26.382+0000] {taskinstance.py:2728} ERROR - Task failed with exception
Traceback (most recent call last):
  File "/home/airflow/.local/lib/python3.8/site-packages/airflow/models/taskinstance.py", line 444, in _execute_task
    result = _execute_callable(context=context, **execute_callable_kwargs)
  File "/home/airflow/.local/lib/python3.8/site-packages/airflow/models/taskinstance.py", line 414, in _execute_callable
    return execute_callable(context=context, **execute_callable_kwargs)
  File "/home/airflow/.local/lib/python3.8/site-packages/airflow/operators/python.py", line 200, in execute
    return_value = self.execute_callable()
  File "/home/airflow/.local/lib/python3.8/site-packages/airflow/operators/python.py", line 217, in execute_callable
    return self.python_callable(*self.op_args, **self.op_kwargs)
  File "/opt/airflow/dags/netflix_dag.py", line 38, in extract_titles
    if not data["results"]:
KeyError: 'results'
[2024-03-10T22:09:26.402+0000] {taskinstance.py:1149} INFO - Marking task as UP_FOR_RETRY. dag_id=netflix_etl_dag, task_id=extract_data_task, execution_date=20240310T220919, start_date=20240310T220924, end_date=20240310T220926
[2024-03-10T22:09:26.425+0000] {standard_task_runner.py:107} ERROR - Failed to execute job 66 for task extract_data_task ('results'; 256)
[2024-03-10T22:09:26.440+0000] {local_task_job_runner.py:234} INFO - Task exited with return code 1
[2024-03-10T22:09:26.464+0000] {taskinstance.py:3309} INFO - 0 downstream tasks scheduled from follow-on schedule check
